#include <iostream>
int main() {
    try {                                        // Beginn des try-Blocks
        for(int n=1; ; n=n*2) {
            if(n < 0) {
                throw "Es gab einen Ueberlauf";  // Fehler auslÃ¶sen
            }
        }
    }                                            // Ende des try-Blocks
    catch(const char *fehler) {                  // falls dieser Fehler auftritt, ...
      std::cout << "Fehler: " << fehler << "\n"; // ... behandle ihn so
    }
}

